#VRML_SIM R2022b utf8
WorldInfo {
  info [
    "Universal Robot UR3e, UR5e and UR10e grasping cans using Robotiq 3F grippers."
  ]
  title "Universal Robot"
  basicTimeStep 24
  physicsDisableAngularThreshold 0.1
}
Viewpoint {
  fieldOfView 0.9
  orientation 0.22688720072604698 -0.05775430138961527 -0.9722070966711237 3.6702094827050598
  position 3.0678600071541156 -2.035411236388436 1.8197543605186324
  exposure 1.7
}
TexturedBackground {
  texture "factory"
}
Floor {
  translation 0.75 0 0
  size 7.5 5
  appearance ThreadMetalPlate {
  }
}
SquareManhole {
  translation 0.560459 -1.782 -0.03
  rotation 0 0 1 -1.5707963071795863
}
Table {
  translation 3.097723 2.013972 0
  size 1.8 0.7 0.8
  feetSize 0.05 0.05
  trayAppearance PBRAppearance {
    baseColor 0.926 0.912 0.698
    roughness 0.8
    metalness 0
  }
  legAppearance BrushedAluminium {
    colorOverride 0.333 0.341 0.325
  }
}
WoodenChair {
  translation 2.921084 1.648051 0
  rotation 0 0 1 2.0944
}
Transform {
  translation 2.52024 2.10889 0.796
  rotation 0 0 1 -1.3089953071795861
  children [
    Monitor {
    }
  ]
}
Keyboard {
  translation 2.59421 1.8802 0.8
  rotation 0 0 1 1.8326
}
DesktopComputer {
  translation 2.331033 2.125086 0
  rotation 0 0 -1 1.5708
}
ComputerMouse {
  translation 2.90217 1.90622 0.81
  rotation 0 0 -1 -1.5707953071795862
  mass 0
}
Table {
  translation -1.419911 -0.81333 0
  rotation 0 0 1 -1.5707963071795863
  name "table(1)"
  size 1.8 0.7 0.8
  feetSize 0.05 0.05
  trayAppearance PBRAppearance {
    baseColor 0.926 0.912 0.698
    roughness 0.8
    metalness 0
  }
  legAppearance BrushedAluminium {
    colorOverride 0.333 0.341 0.325
  }
}
OfficeTelephone {
  translation -1.34381 -0.209288 0.8
  rotation 0 0 1 -2.3561953071795863
  enablePhysics FALSE
}
Wrench {
  translation -1.23886 -0.5886 0.8
  rotation 0 0 1 -2.6179953071795863
}
Hammer {
  translation -1.60381 -0.359288 0.81
  rotation 0 0 1 1.5708
}
PlatformCart {
  translation 0.927687 1.793317 0
  rotation 0 0 1 -2.8797933071795865
}
Radiator {
  translation 0.528902 2.341308 0.33
  rotation 0 0 1 -1.5707963071795863
  numberOfFins 16
}
WoodenPalletStack {
  translation 2.8 0.16 0
  rotation 0 0 1 -1.5707953071795862
  palletNumber 5
  palletSize 0.8 1 0.11
}
Cabinet {
  translation -0.41 2.47 0
  rotation 0 0 1 -1.5707953071795862
  name "cabinet(1)"
  layout [
    "RightSidedDoor (1, 1, 1, 5, 1.5)"
    "LeftSidedDoor (2, 1, 2, 5, 1.5)"
  ]
  primaryAppearance GlossyPaint {
    baseColor 0.729 0.741 0.713
  }
  secondaryAppearance GlossyPaint {
    baseColor 0.729 0.741 0.713
  }
}
CardboardBox {
  translation -1.21 2.18 0.3
}
CardboardBox {
  translation -1.198389 2.100678 0.75
  rotation 0 0 1 2.094395
  name "cardboard box(1)"
  size 0.4 0.6 0.3
}
Solid {
  translation -0.38 2.16 0.06
  children [
    DEF GEOM Shape {
      appearance PBRAppearance {
        baseColorMap ImageTexture {
          url [
            "https://raw.githubusercontent.com/cyberbotics/webots/develop/projects/objects/toys/protos/PaperBoat/textures/newspaper.jpg"
          ]
        }
        roughness 1
        metalness 0
      }
      geometry Mesh {
        url [
          "https://raw.githubusercontent.com/cyberbotics/webots/master/projects/objects/toys/protos/PaperBoat/meshes/geom.obj"
        ]
      }
    }
  ]
  name "solid(2)"
  immersionProperties [
    ImmersionProperties {
      fluidName "water"
      dragForceCoefficients 0.05 0 0
      viscousResistanceForceCoefficient 200
    }
  ]
}
Transform {
  translation 1.77 2.67 1.05
  rotation 1 0 0 1.5707996938995747
  children [
    Shape {
      appearance PBRAppearance {
        baseColor 0 0 0
        roughness 1
        metalness 0
      }
      geometry Box {
        size 0.23 0.3 0.01
      }
    }
  ]
}
SolidBox {
  translation 0.345 -0.2464 0.215
  rotation 1 0 0 4.692820414042842e-06
  size 1.5 0.4 0.54
  appearance GalvanizedMetal {
  }
}
SolidBox {
  translation -0.015 -0.8323 0.2
  rotation 0 0 1 -1.5707953071795862
  name "box(2)"
  size 0.77 0.8 0.39
  appearance GalvanizedMetal {
  }
}
Robot {
  translation 0.4 -0.33 0.494
  rotation 0 0 -1 1.5708
  children [
    Group {
      children [
        CapScrew {
          translation 0.02166 0.0493 0.431
          rotation 0 1 0 1.5708
          appearance GalvanizedMetal {
          }
          screwRadius 0.003
          screwLength 0.02
          enablePhysics FALSE
          enableBoundingObject FALSE
        }
        CapScrew {
          translation 0.098 0.0493 0.431
          rotation 0 1 0 1.5708
          name "cap screw(1)"
          appearance GalvanizedMetal {
          }
          screwRadius 0.003
          screwLength 0.02
          enablePhysics FALSE
          enableBoundingObject FALSE
        }
        CapScrew {
          translation 0.098 -0.0507 0.431
          rotation 0 1 0 1.5708
          name "cap screw(2)"
          appearance GalvanizedMetal {
          }
          screwRadius 0.003
          screwLength 0.02
          enablePhysics FALSE
          enableBoundingObject FALSE
        }
        CapScrew {
          translation 0.0215 -0.0497 0.431
          rotation 0 1 0 1.5708
          name "cap screw(3)"
          appearance GalvanizedMetal {
          }
          screwRadius 0.003
          screwLength 0.02
          enablePhysics FALSE
          enableBoundingObject FALSE
        }
        CapScrew {
          translation -0.0477 -0.0494 0.4091
          rotation 0 1 0 1.0472053071795866
          name "cap screw(4)"
          appearance GalvanizedMetal {
          }
          screwRadius 0.003
          screwLength 0.02
          enablePhysics FALSE
          enableBoundingObject FALSE
        }
        CapScrew {
          translation -0.0921 -0.0493 0.3583
          name "cap screw(6)"
          appearance GalvanizedMetal {
          }
          screwRadius 0.003
          screwLength 0.02
          enablePhysics FALSE
          enableBoundingObject FALSE
        }
        CapScrew {
          translation -0.0934 -0.05565 0.2079
          name "cap screw(8)"
          appearance GalvanizedMetal {
          }
          screwRadius 0.002
          screwLength 0.02
          enablePhysics FALSE
          enableBoundingObject FALSE
        }
        CapScrew {
          translation -0.0934 -0.05565 0.2382
          name "cap screw(9)"
          appearance GalvanizedMetal {
          }
          screwRadius 0.002
          screwLength 0.02
          enablePhysics FALSE
          enableBoundingObject FALSE
        }
        CapScrew {
          translation -0.0932 0.05565 0.2383
          name "cap screw(10)"
          appearance GalvanizedMetal {
          }
          screwRadius 0.002
          screwLength 0.02
          enablePhysics FALSE
          enableBoundingObject FALSE
        }
        CapScrew {
          translation -0.0934 0.05565 0.2078
          name "cap screw(11)"
          appearance GalvanizedMetal {
          }
          screwRadius 0.002
          screwLength 0.02
          enablePhysics FALSE
          enableBoundingObject FALSE
        }
        CapScrew {
          translation -0.0934 0.05565 -0.0014
          name "cap screw(12)"
          appearance GalvanizedMetal {
          }
          screwRadius 0.002
          screwLength 0.02
          enablePhysics FALSE
          enableBoundingObject FALSE
        }
        CapScrew {
          translation -0.0934 -0.05569 -0.0014
          name "cap screw(13)"
          appearance GalvanizedMetal {
          }
          screwRadius 0.002
          screwLength 0.02
          enablePhysics FALSE
          enableBoundingObject FALSE
        }
        CapScrew {
          translation -0.0921 0.0498 0.3583
          name "cap screw(7)"
          appearance GalvanizedMetal {
          }
          screwRadius 0.003
          screwLength 0.02
          enablePhysics FALSE
          enableBoundingObject FALSE
        }
        CapScrew {
          translation -0.0477 0.0496 0.4091
          rotation 0 1 0 1.0472053071795866
          name "cap screw(5)"
          appearance GalvanizedMetal {
          }
          screwRadius 0.003
          screwLength 0.02
          enablePhysics FALSE
          enableBoundingObject FALSE
        }
      ]
    }
    DEF MAIN_BASE Shape {
      appearance Plaster {
        textureTransform TextureTransform {
          scale 100 100
        }
      }
      geometry Mesh {
        url [
          "webots://projects/robots/epson/scara_t6/protos/meshes/base.obj"
        ]
      }
    }
    DEF MAIN_CONNECTOR Shape {
      appearance RoughPolymer {
        baseColor 0 0 0
      }
      geometry Mesh {
        url [
          "webots://projects/robots/epson/scara_t6/protos/meshes/main_connector.obj"
        ]
      }
    }
    DEF CONNECTOR Shape {
      appearance BrushedAluminium {
        colorOverride 0.533333 0.541176 0.521569
      }
      geometry Mesh {
        url [
          "webots://projects/robots/epson/scara_t6/protos/meshes/connector.obj"
        ]
      }
    }
    DEF NUTS Shape {
      appearance BrushedAluminium {
        colorOverride 0.533333 0.541176 0.521569
      }
      geometry Mesh {
        url [
          "webots://projects/robots/epson/scara_t6/protos/meshes/nuts.obj"
        ]
      }
    }
    DEF BULB_SOCKET Shape {
      appearance BrushedAluminium {
        colorOverride 0.533333 0.541176 0.521569
      }
      geometry Mesh {
        url [
          "webots://projects/robots/epson/scara_t6/protos/meshes/bulb_socket.obj"
        ]
      }
    }
    LED {
      children [
        Group {
          children [
            PointLight {
              attenuation 0 0 1
              color 1 0.10000000149011612 0
              intensity 0.05
              location 0.023 0.028 0.451
              on FALSE
              radius 1
              castShadows TRUE
            }
            Shape {
              appearance PBRAppearance {
                baseColor 1 0.270588 0
                transparency 0.01
                roughness 0.2
                metalness 0.8
              }
              geometry Mesh {
                url [
                  "webots://projects/robots/epson/scara_t6/protos/meshes/bulb.obj"
                ]
              }
            }
          ]
        }
      ]
      name "epson_led"
      color [
        1 0.1 0
      ]
    }
    DEF LINK1_HINGEJOINT HingeJoint {
      jointParameters HingeJointParameters {
        axis 0 0 1
        anchor 0.06 0 0.22
      }
      device [
        RotationalMotor {
          name "base_arm_motor"
          maxVelocity 12.82
          minPosition -0.73
          maxPosition 0.73
          maxTorque 100
        }
        PositionSensor {
          name "base_arm_position"
        }
      ]
      endPoint Solid {
        children [
          DEF BASE_ARM Transform {
            translation 0.06 0.0045 0.196
            children [
              Shape {
                appearance Plaster {
                  textureTransform TextureTransform {
                    scale 100 100
                  }
                }
                geometry Mesh {
                  url [
                    "webots://projects/robots/epson/scara_t6/protos/meshes/base_arm.obj"
                  ]
                }
              }
            ]
          }
          DEF CABLE Solid {
            translation 0.06 0 0.423
            rotation 0 0 1 -1.5708
            children [
              Shape {
                appearance RoughPolymer {
                  baseColor 0 0 0
                }
                geometry DEF CABLE_MESH Mesh {
                  url [
                    "webots://projects/robots/epson/scara_t6/protos/meshes/cable.obj"
                  ]
                }
              }
            ]
            name "cable_solid"
          }
          Transform {
            translation 0.363 0 0.256
            children [
              DEF LINK2_HINGEJOINT HingeJoint {
                jointParameters HingeJointParameters {
                  axis 0 0 1
                  anchor 0.007 0.005 -0.04
                }
                device [
                  RotationalMotor {
                    name "arm_motor"
                    maxVelocity 12.82
                    minPosition -0.83
                    maxPosition 0.83
                    maxTorque 100
                  }
                  PositionSensor {
                    name "arm_position"
                  }
                ]
                endPoint DEF ARM Solid {
                  children [
                    CapScrew {
                      translation -0.02 -0.0434 0.0508
                      rotation 0 1 0 1.5708
                      name "cap screw(1)"
                      appearance GalvanizedMetal {
                      }
                      screwRadius 0.003
                      screwLength 0.02
                      enablePhysics FALSE
                      enableBoundingObject FALSE
                    }
                    CapScrew {
                      translation -0.02 0.0431 0.0508
                      rotation 0 1 0 1.5708
                      appearance GalvanizedMetal {
                      }
                      screwRadius 0.003
                      screwLength 0.02
                      enablePhysics FALSE
                      enableBoundingObject FALSE
                    }
                    CapScrew {
                      translation -0.0251 0.019 0.1828
                      rotation 0 1 0 1.5708
                      name "cap screw(2)"
                      appearance GalvanizedMetal {
                      }
                      screwRadius 0.00261
                      screwLength 0.01
                      enablePhysics FALSE
                      enableBoundingObject FALSE
                    }
                    CapScrew {
                      translation -0.0251 -0.019 0.1828
                      rotation 0 1 0 1.5708
                      name "cap screw(3)"
                      appearance GalvanizedMetal {
                      }
                      screwRadius 0.00261
                      screwLength 0.01
                      enablePhysics FALSE
                      enableBoundingObject FALSE
                    }
                    CapScrew {
                      translation 0.098538 -0.0257 0.1828
                      rotation 0 1 0 1.5708
                      name "cap screw(4)"
                      appearance GalvanizedMetal {
                      }
                      screwRadius 0.00261
                      screwLength 0.01
                      enablePhysics FALSE
                      enableBoundingObject FALSE
                    }
                    CapScrew {
                      translation 0.098538 0.0257 0.1828
                      rotation 0 1 0 1.5708
                      name "cap screw(5)"
                      appearance GalvanizedMetal {
                      }
                      screwRadius 0.00261
                      screwLength 0.01
                      enablePhysics FALSE
                      enableBoundingObject FALSE
                    }
                    CapScrew {
                      translation -0.0476 -0.01371 0.0509
                      name "cap screw(7)"
                      appearance GalvanizedMetal {
                      }
                      screwRadius 0.0029
                      screwLength 0.01
                      enablePhysics FALSE
                      enableBoundingObject FALSE
                    }
                    CapScrew {
                      translation -0.0476 0.0131 0.0509
                      name "cap screw(6)"
                      appearance GalvanizedMetal {
                      }
                      screwRadius 0.0029
                      screwLength 0.01
                      enablePhysics FALSE
                      enableBoundingObject FALSE
                    }
                    Shape {
                      appearance Plaster {
                        textureTransform TextureTransform {
                          scale 100 100
                        }
                      }
                      geometry Mesh {
                        url [
                          "webots://projects/robots/epson/scara_t6/protos/meshes/arm.obj"
                        ]
                      }
                    }
                    Shape {
                      appearance BrushedAluminium {
                        colorOverride 0.533333 0.541176 0.521569
                      }
                      geometry Mesh {
                        url [
                          "webots://projects/robots/epson/scara_t6/protos/meshes/arm_nuts.obj"
                        ]
                      }
                    }
                    Shape {
                      appearance PBRAppearance {
                        baseColor 0 0 1
                        roughness 0.2
                        metalness 0
                      }
                      geometry Mesh {
                        url [
                          "webots://projects/robots/epson/scara_t6/protos/meshes/button.obj"
                        ]
                      }
                    }
                    Shape {
                      appearance BrushedAluminium {
                        colorOverride 0.533333 0.541176 0.521569
                      }
                      geometry Mesh {
                        url [
                          "webots://projects/robots/epson/scara_t6/protos/meshes/button_socket.obj"
                        ]
                      }
                    }
                    DEF LOGO_LEFT Transform {
                      translation 0.0695 -0.0568 0.092
                      rotation 1 0 0 1.5608
                      children [
                        DEF EPSON_LOGO Shape {
                          appearance PBRAppearance {
                            baseColorMap ImageTexture {
                              url [
                                "webots://projects/robots/epson/scara_t6/protos/textures/epson.png"
                              ]
                              repeatT FALSE
                            }
                            roughness 1
                            metalness 0
                          }
                          geometry Plane {
                            size 0.11 0.024
                          }
                        }
                      ]
                    }
                    DEF LOGO_RIGHT Transform {
                      translation 0.0695 0.0565 0.092
                      rotation 0.0035005071727176335 -0.7071024488889619 -0.7071024488889619 3.14158
                      children [
                        USE EPSON_LOGO
                      ]
                    }
                    DEF LINK3_HINGEJOINT HingeJoint {
                      jointParameters HingeJointParameters {
                        axis 0 0 1
                        anchor 0.2615 0 0
                      }
                      device [
                        RotationalMotor {
                          name "shaft_rotation_motor"
                          maxVelocity 1.8
                        }
                        PositionSensor {
                          name "shaft_rotation_position"
                        }
                      ]
                      endPoint Solid {
                        translation 0.2615 0 0
                        children [
                          DEF Shaft SliderJoint {
                            jointParameters JointParameters {
                            }
                            device [
                              LinearMotor {
                                name "shaft_linear_motor"
                                minPosition -0.2
                                maxForce 58.9
                              }
                              PositionSensor {
                                name "shaft_linear_position"
                              }
                            ]
                            endPoint Solid {
                              children [
                                DEF HAND_SLOT Transform {
                                  translation 0 0 -0.074
                                  children [
                                    DEF VACCUM Transform {
                                      children [
                                        Shape {
                                          appearance ElectricConduit {
                                          }
                                          geometry Cylinder {
                                            height 0.04
                                            radius 0.11
                                          }
                                        }
                                      ]
                                    }
                                  ]
                                }
                                DEF SHAFT Transform {
                                  translation 0 0 0.348
                                  children [
                                    Shape {
                                      appearance BrushedAluminium {
                                      }
                                      geometry Mesh {
                                        url [
                                          "webots://projects/robots/epson/scara_t6/protos/meshes/shaft.obj"
                                        ]
                                      }
                                    }
                                  ]
                                }
                              ]
                              name "shaft_solid"
                              boundingObject DEF SHAFT_BOUND Transform {
                                translation 0 0 0.137
                                children [
                                  Shape {
                                    geometry Cylinder {
                                      height 0.446
                                      radius 0.01
                                    }
                                  }
                                ]
                              }
                              physics Physics {
                                density -1
                                mass 0.8
                              }
                            }
                          }
                        ]
                        physics Physics {
                          density -1
                          mass 0.001
                          centerOfMass [
                            0 0 0
                          ]
                          inertiaMatrix [
                            1 1 1
                            0 0 0
                          ]
                        }
                      }
                    }
                  ]
                  name "arm_solid"
                  boundingObject DEF ARM_BOUND Transform {
                    translation 0.1015 0 0.087
                    children [
                      Box {
                        size 0.292 0.126 0.19
                      }
                    ]
                  }
                  physics Physics {
                    density -1
                    mass 1
                  }
                }
              }
            ]
          }
        ]
        name "base_arm_solid"
        boundingObject DEF BASE_ARM_BOUND Transform {
          translation 0.204 0.0045 0.22
          children [
            Box {
              size 0.403 0.1 0.05
            }
          ]
        }
        physics Physics {
          density -1
          mass 2
        }
      }
    }
  ]
  name "ScaraT6"
  model "SCARA EPSON T6‑602S"
  description "4-axis Scara robot, payload is up to 6kg and the reach is 600mm."
  boundingObject DEF BASE_BOUND Transform {
    translation 0.013 0 0.214
    children [
      Box {
        size 0.216 0.12 0.45
      }
    ]
  }
  controller "scara_food_industry"
  supervisor TRUE
}
FireExtinguisher {
  translation -0.75771 1.79 0
  rotation 0 0 -1 1.5708
}
ConveyorBelt {
  translation 2.48 -0.83 0
  rotation 0 0 1 3.14159
  size 4.12 0.7 0.4
  appearance CorrugatedMetal {
    textureTransform TextureTransform {
      scale 6 3.1
    }
  }
  borderHeight 0.1
  speed 0.1
}
PlasticCrate {
  translation 0.58 0.42 0
  size 0.6 0.45 0.4
  mass 1
}
PlasticCrate {
  translation -0.08 -0.82 0.395
  rotation 0 0 1 1.01503e-06
  name "plastic crate(2)"
  size 0.3 0.44 0.1
  color 0.913725 0.72549 0.431373
  mass 1
}
PlasticCrate {
  translation 0.22214 -0.830233 0.395
  rotation 0 0 1 1.01503e-06
  name "plastic crate(3)"
  size 0.3 0.44 0.1
  color 0.913725 0.72549 0.431373
  mass 1
}
PlasticCrate {
  translation -0.1 0.42 0
  name "plastic crate(1)"
  size 0.6 0.45 0.4
  color 0.827451 0.843137 0.811765
  mass 1
}
DEF WALL1 Transform {
  translation 0.75 2.5 1
  rotation 1 0 0 1.5708
  children [
    DEF wall_long Shape {
      appearance Roughcast {
      }
      geometry Plane {
        size 7.5 2
      }
    }
  ]
}
DEF WALL2 Transform {
  translation 0.75 -2.5 1
  rotation 1 0 0 -1.5708
  children [
    USE wall_long
  ]
}
DEF WALL3 Transform {
  translation 4.5 0 1
  rotation -0.5773509358554485 0.5773489358556708 0.5773509358554485 -2.094395307179586
  children [
    DEF wall_short Shape {
      appearance Roughcast {
      }
      geometry Plane {
        size 5 2
      }
    }
  ]
}
DEF WALL4 Transform {
  translation -3 0 1
  rotation 0.5773506025225371 0.5773496025232256 0.5773506025225371 2.0944
  children [
    USE wall_short
  ]
}
Transform {
  translation 4.5 -0.83 0.65
  children [
    Shape {
      appearance Plastic {
        colorOverride 0 0 0
      }
      geometry Box {
        size 0.001 0.7 0.5
      }
    }
  ]
}
Orange {
  translation 0.525834 -1.07997 0.44
  name "orange(2)"
}
Orange {
  translation 1.58807 -0.833874 0.44
  name "orange(7)"
}
Orange {
  translation 1.54699 -0.990903 0.44
  name "orange(24)"
}
Orange {
  translation 1.17992 -0.738513 0.44
  name "orange(13)"
}
Orange {
  translation 2.58229 -1.01985 0.44
  name "orange(10)"
}
Orange {
  translation 3.06296 -0.726633 0.44
  name "orange(11)"
}
Orange {
  translation 3.35401 -0.891637 0.44
  name "orange(12)"
}
Orange {
  translation 3.67228 -0.909649 0.44
  name "orange(17)"
}
Orange {
  translation 4.17121 -0.948107 0.44
  name "orange(16)"
}
Orange {
  translation 3.01257 -0.999581 0.44
  name "orange(15)"
}
Orange {
  translation 1.80125 -0.978805 0.44
  name "orange(9)"
}
Orange {
  translation 2.0482 -0.853736 0.44
  name "orange(18)"
}
Orange {
  translation 0.527005 -0.59888 0.44
  name "orange(1)"
}
Orange {
  translation 0.89708 -0.999981 0.44
  name "orange(8)"
}
Orange {
  translation 0.701031 -0.619505 0.44
  rotation 0 1 0 0.523599
  name "orange(14)"
}
Orange {
  translation 1.06056 -0.965735 0.44
  name "orange(20)"
}
Orange {
  translation 0.979007 -0.724324 0.44
  name "orange(23)"
}
Orange {
  translation 0.519285 -0.762303 0.44
  name "orange(22)"
}
Orange {
  translation 0.837455 -0.676998 0.44
  name "orange(19)"
}
DEF fruit1 Orange {
  translation 0.677164 -0.812413 0.44
  name "orange(21)"
}
Orange {
  translation 0.141124 -0.774816 0.44
  name "orange(3)"
}
Orange {
  translation 0.244109 -0.70797 0.445869
  rotation 0 1 0 1.309
  name "orange(4)"
}
Orange {
  translation 0.14233 -0.922713 0.451045
  rotation 0.09269091803692169 0.7040681370061072 -0.7040571370039667 0.369707
  name "orange(5)"
}
Orange {
  translation 0.265314 -0.847889 0.453
  name "orange(6)"
}
DEF fruit0 Apple {
  translation 0.623758 -0.897132 0.45
  rotation 0 0 1 -0.523595307179586
  name "apple(10)"
}
Apple {
  translation 1.83364 -0.629035 0.45
  rotation 0 0 1 -0.523595307179586
}
Apple {
  translation 1.20145 -0.95923 0.45
  rotation 0 0 1 -0.523595307179586
  name "apple(15)"
}
Apple {
  translation 2.24739 -0.796399 0.45
  rotation 0 0 1 -0.523595307179586
  name "apple(6)"
}
Apple {
  translation 2.70197 -0.898415 0.45
  rotation 0 0 1 -0.523595307179586
  name "apple(7)"
}
Apple {
  translation 3.56635 -0.773122 0.45
  rotation 0 0 1 -0.523595307179586
  name "apple(14)"
}
Apple {
  translation 2.39677 -0.941142 0.45
  rotation 0 0 1 -0.523595307179586
  name "apple(8)"
}
Apple {
  translation 3.87772 -1.06219 0.45
  rotation 0 0 1 -0.523595307179586
  name "apple(12)"
}
Apple {
  translation 4.23807 -0.665014 0.45
  rotation 0 0 1 -0.523595307179586
  name "apple(13)"
}
Apple {
  translation 0.527099 -0.932775 0.45
  rotation 0 0 1 -0.523595307179586
  name "apple(5)"
}
Apple {
  translation 0.704774 -1.00551 0.45
  rotation 0 0 1 -0.523595307179586
  name "apple(11)"
}
Apple {
  translation 0.794774 -0.84963 0.45
  rotation 0.9999999999897413 1.7334099999822177e-06 -4.184819999957069e-06 -0.785395307179586
  name "apple(9)"
}
Apple {
  translation 0.947486 -0.846641 0.45
  rotation 0.11734400095887651 0.4379360035785941 -0.8913150072833806 0.584052
  name "apple(16)"
}
Apple {
  translation 1.12263 -0.614939 0.45
  rotation 0 0 1 -0.523595307179586
  name "apple(17)"
}
Apple {
  translation 1.36413 -0.798103 0.45
  rotation 0 0 1 -0.523595307179586
  name "apple(18)"
}
Apple {
  translation 1.34757 -1.00584 0.45
  rotation 0 0 1 -0.523595307179586
  name "apple(19)"
}
Apple {
  translation 1.62579 -0.70485 0.45
  rotation 0 0 1 -0.523595307179586
  name "apple(20)"
}
Apple {
  translation -0.00714131 -0.706077 0.45
  rotation 0.46112910766674226 -0.5893351376009307 -0.6633581548841968 -2.1588553071795866
  name "apple(1)"
}
Apple {
  translation -0.162059 -0.915421 0.45
  rotation 0 0 1 -0.523595307179586
  name "apple(2)"
}
Apple {
  translation -0.133885 -0.736342 0.45
  rotation 0 0 1 -0.523595307179586
  name "apple(4)"
}
Apple {
  translation -0.0126866 -0.903111 0.45
  rotation 0.9999999999959461 1.733409999992973e-06 -2.2590199999908423e-06 -1.3089953071795861
  name "apple(3)"
}
