
#VRML_SIM R2022a utf8
# license: Copyright Cyberbotics Ltd. Licensed for use only with Webots.
# license url: https://cyberbotics.com/webots_assets_license
# documentation url: https://www.cyberbotics.com/doc/guide/irb4600-40
# Tracked robot

PROTO trackedRobot [
  field SFVec3f    translation     0 0 0.25              # Is `Transform.translation`.
  field SFRotation rotation        0 0 1 0               # Is `Transform.rotation`.
  field SFString   name            "trackedRobot"        # Is `Solid.name`.
  field SFString   controller      ""                    # Is `Robot.controller`.
  field MFString   controllerArgs  []                    # Is `Robot.controllerArgs`.
  field SFString   customData      ""                    # Is `Robot.customData`.
  field SFBool     supervisor      FALSE                 # Is `Robot.supervisor`.
  field SFBool     synchronization TRUE                  # Is `Robot.synchronization`.
  field MFNode     bodySlot        []
]
{
Robot {
  translation IS translation
  rotation IS rotation
  name IS name
  children [
    Transform {
      translation 0.71 0 0
      rotation 1 0 0 1.5708
      children [
        DEF GEOM_1 Shape {
          appearance Plastic {
            colorOverride 0.180392 0.203922 0.211765
          }
          geometry Cylinder {
            height 0.9195
            radius 0.16
          }
        }
      ]
    }
    Transform {
      translation -0.71 0 0
      rotation 1 0 0 1.5708
      children [
        Shape {
          appearance Plastic {
            colorOverride 0.180392 0.203922 0.211765
          }
          geometry Cylinder {
            height 0.9195
            radius 0.16
          }
        }
      ]
    }
    Transform {
      translation 0 0 0
      rotation 0 1 0 0
      children [
        DEF GEOM Shape {
          appearance Plastic {
            colorOverride 0.180392 0.203922 0.211765
          }
          geometry Box {
            size 1.42 0.92 0.32
          }
        }
      ]
    }
    Transform {
      children IS bodySlot
    }
    DEF LEFT_TRACK Track {
      translation 0 0.55 -0.0129
      children [
        DEF WHEEL1 TrackWheel {
          position -0.71 0.03
          radius 0.2
          children [
            DEF TRACK_WHEEL_BIG Transform {
              rotation -1 0 0 3.141589
              children [
                Shape {
                  appearance PBRAppearance {
                    baseColorMap ImageTexture {
                      url [
                        "https://raw.githubusercontent.com/cyberbotics/webots/master/projects/samples/devices/worlds/textures/tank_wheel.jpg"
                      ]
                    }
                    roughness 1
                    metalness 0
                  }
                  geometry Cylinder {
                    height 0.18
                    radius 0.2
                    side FALSE
                    subdivision 20
                  }
                }
                Shape {
                  appearance ThreadMetalPlate {
                    textureTransform TextureTransform {
                      scale 0.2 1
                    }
                  }
                  geometry Cylinder {
                    height 0.179
                    radius 0.2
                    top FALSE
                    subdivision 20
                  }
                }
              ]
            }
          ]
        }
        DEF WHEEL2 TrackWheel {
          position 0.71 0.03
          radius 0.2
          children [
            USE TRACK_WHEEL_BIG
          ]
        }
        DEF WHEEL3 TrackWheel {
          position 0.42 -0.176
          radius 0.14
          children [
            DEF TRACK_WHEEL_SMALL Transform {
              rotation -1 0 0 3.141589
              children [
                Shape {
                  appearance PBRAppearance {
                    baseColorMap ImageTexture {
                      url [
                        "https://raw.githubusercontent.com/cyberbotics/webots/master/projects/samples/devices/worlds/textures/tank_wheel.jpg"
                      ]
                    }
                    roughness 1
                    metalness 0
                  }
                  geometry Cylinder {
                    height 0.18
                    radius 0.14
                    side FALSE
                    subdivision 20
                  }
                }
                Shape {
                  appearance ThreadMetalPlate {
                    textureTransform TextureTransform {
                      scale 0.2 1
                    }
                  }
                  geometry Cylinder {
                    height 0.179
                    radius 0.14
                    top FALSE
                    subdivision 20
                  }
                }
              ]
            }
          ]
        }
        DEF WHEEL4 TrackWheel {
          position 0.14 -0.176
          radius 0.14
          children [
            USE TRACK_WHEEL_SMALL
          ]
        }
        DEF WHEEL5 TrackWheel {
          position -0.14 -0.176
          radius 0.14
          children [
            USE TRACK_WHEEL_SMALL
          ]
        }
        DEF WHEEL6 TrackWheel {
          position -0.42 -0.176
          radius 0.14
          children [
            USE TRACK_WHEEL_SMALL
          ]
        }
      ]
      name "left track"
      contactMaterial "track material"
      boundingObject DEF TRACK_BO Group {
        children [
          Transform {
            translation 0 0 -0.05
            rotation 1 0 0 1.570796
            children [
              Box {
                size 0.9 0.54 0.18
              }
            ]
          }
          Transform {
            translation 0.54 0 -0.19
            rotation 0.9561247250869316 -0.20715394043734683 0.20715394043734683 1.615648
            children [
              Box {
                size 0.26 0.16 0.18
              }
            ]
            translationStep 0.001
            rotationStep 0.00261799
          }
          Transform {
            translation -0.54 0 -0.19
            rotation 0.959691189146035 0.19873703916918628 -0.19873703916918628 1.611928
            children [
              Box {
                size 0.26 0.16 0.18
              }
            ]
            translationStep 0.001
            rotationStep 0.00261799
          }
          Transform {
            translation -0.71 0 0.03
            rotation 1 0 0 1.5708
            children [
              DEF WHEEL_BO Cylinder {
                height 0.18
                radius 0.2
                subdivision 16
              }
            ]
          }
          Transform {
            translation 0.71 0 0.03
            rotation 1 0 0 1.5708
            children [
              USE WHEEL_BO
            ]
          }
        ]
      }
      physics Physics {
      }
      device [
        LinearMotor {
          name "left motor"
        }
      ]
      animatedGeometry DEF ANIMATED_GEOM Group {
        children [
          Shape {
            appearance PBRAppearance {
              baseColor 0.141176 0.141176 0.141176
              roughness 1
              metalness 0
            }
            geometry Box {
              size 0.088 0.18 0.01
            }
          }
          Transform {
            translation 0 0 0.012
            children [
              Shape {
                appearance PBRAppearance {
                  baseColor 0.141176 0.141176 0.141176
                  roughness 1
                  metalness 0
                }
                geometry Box {
                  size 0.04 0.18 0.014
                }
              }
            ]
          }
        ]
      }
      geometriesCount 47
    }
    Track {
      translation 0 -0.55 -0.0129
      children [
        TrackWheel {
          position -0.71 0.03
          radius 0.2
          children [
            USE TRACK_WHEEL_BIG
          ]
        }
        TrackWheel {
          position 0.71 0.03
          radius 0.2
          children [
            USE TRACK_WHEEL_BIG
          ]
        }
        TrackWheel {
          position 0.42 -0.176
          radius 0.14
          children [
            USE TRACK_WHEEL_SMALL
          ]
        }
        TrackWheel {
          position 0.14 -0.176
          radius 0.14
          children [
            USE TRACK_WHEEL_SMALL
          ]
        }
        TrackWheel {
          position -0.14 -0.176
          radius 0.14
          children [
            USE TRACK_WHEEL_SMALL
          ]
        }
        TrackWheel {
          position -0.42 -0.176
          radius 0.14
          children [
            USE TRACK_WHEEL_SMALL
          ]
        }
      ]
      name "right track"
      contactMaterial "track material"
      boundingObject USE TRACK_BO
      physics Physics {
      }
      device [
        LinearMotor {
          name "right motor"
        }
      ]
      animatedGeometry USE ANIMATED_GEOM
      geometriesCount 40
    }
    DEF CAMERA Transform {
      translation 0.54 0 0.117
      rotation 0 0 1 3.14159
      children [
        DEF CAMERA_TILT HingeJoint {
          jointParameters HingeJointParameters {
            axis 0 0 1
            anchor 0 0 0.065
          }
          device [
            RotationalMotor {
              name "camera_tilt_motor"
              minPosition -3.14159
              maxPosition 3.14159
            }
          ]
          endPoint Solid {
            children [
              DEF LENS Transform {
                translation -0.0255 0 0.2735
                rotation 0 1 0 -1.5707953071795862
                children [
                  Shape {
                    appearance PBRAppearance {
                    }
                    geometry Cylinder {
                      height 0.001
                      radius 0.0023
                    }
                  }
                ]
              }
              DEF SHAFT Transform {
                children [
                  Shape {
                    appearance Plastic {
                      colorOverride 0.180392 0.203922 0.211765
                    }
                    geometry Mesh {
                      url [
                        "meshes/shaft.obj"
                      ]
                    }
                  }
                ]
              }
              DEF CAMERA_PAN HingeJoint {
                jointParameters HingeJointParameters {
                  axis 0 1 0
                  anchor 0 0 0.273
                }
                device [
                  RotationalMotor {
                    name "camera_pan_motor"
                    minPosition -1.35
                    maxPosition 1.35
                  }
                ]
                endPoint Solid {
                  children [
                    Shape {
                      appearance Plastic {
                        colorOverride 0.180392 0.203922 0.211765
                      }
                      geometry Mesh {
                        url [
                          "meshes/camera.obj"
                        ]
                      }
                    }
                    Camera {
                      translation -0.02 0 0.273
                      rotation 0 0 1 3.14156
                    }
                  ]
                }
              }
            ]
          }
        }
      ]
    }
    DEF ANTENNA_1 Transform {
      translation -0.873 -0.137 0.023
      rotation 0.11611260301955266 0.17784936149720515 -0.9771834362263105 1.58783
      children [
        DEF ANTENNA_SHAPE Shape {
          appearance Plastic {
            colorOverride 0.180392 0.203922 0.211765
          }
          geometry Mesh {
            url [
              "meshes/antenna.obj"
            ]
          }
        }
      ]
    }
    DEF ANTENNA_2 Transform {
      translation -0.873 0.137 0.023
      rotation -0.14253600610763875 -0.08370290358665233 -0.9862440422603559 1.56261
      children [
        USE ANTENNA_SHAPE
      ]
    }
  ]
  boundingObject Group {
    children [
      USE GEOM
      Transform {
        translation 0.611 0 0.01
        rotation 1 0 0 1.5708
        children [
          USE GEOM_1
        ]
      }
      Transform {
        translation -0.55 0 0.01
        rotation 1 0 0 1.5708
        children [
          USE GEOM_1
        ]
      }
    ]
  }
  physics Physics {
    density -1
    mass 40
  }
  controller IS controller
  controllerArgs IS controllerArgs
  customData IS customData
  supervisor IS supervisor
  synchronization IS synchronization
}
}
